{"text": "2022-07-31T11:02:41.055447+0300 | ERROR      | An error has been caught in function '__callback', process 'MainProcess' (16364), thread 'MainThread' (7644):\nTraceback (most recent call last):\n\n  File \"C:\\Users\\phili\\PycharmProjects\\GuildsBot\\bot.py\", line 99, in <module>\n    run()\n    └ <function run at 0x000001DFA2B13490>\n\n  File \"C:\\Users\\phili\\PycharmProjects\\GuildsBot\\bot.py\", line 95, in run\n    bot.run(config.get_token)\n    │   │   │      └ <property object at 0x000001DFA28830B0>\n    │   │   └ <_config.Config object at 0x000001DFA0ECCDF0>\n    │   └ <function Client.run at 0x000001DFA15C1630>\n    └ <nextcord.ext.commands.bot.Bot object at 0x000001DFA2B21DB0>\n\n  File \"C:\\Users\\phili\\PycharmProjects\\GuildsBot\\venv\\lib\\site-packages\\nextcord\\client.py\", line 796, in run\n    loop.run_forever()\n    │    └ <function ProactorEventLoop.run_forever at 0x000001DFA08C0DC0>\n    └ <ProactorEventLoop running=True closed=False debug=False>\n\n  File \"C:\\Users\\phili\\AppData\\Local\\Programs\\Python\\Python310\\lib\\asyncio\\windows_events.py\", line 321, in run_forever\n    super().run_forever()\n\n  File \"C:\\Users\\phili\\AppData\\Local\\Programs\\Python\\Python310\\lib\\asyncio\\base_events.py\", line 600, in run_forever\n    self._run_once()\n    │    └ <function BaseEventLoop._run_once at 0x000001DFA0816170>\n    └ <ProactorEventLoop running=True closed=False debug=False>\n\n  File \"C:\\Users\\phili\\AppData\\Local\\Programs\\Python\\Python310\\lib\\asyncio\\base_events.py\", line 1896, in _run_once\n    handle._run()\n    │      └ <function Handle._run at 0x000001DFA07B1990>\n    └ <Handle Task.task_wakeup(<Future finished result=None>)>\n\n  File \"C:\\Users\\phili\\AppData\\Local\\Programs\\Python\\Python310\\lib\\asyncio\\events.py\", line 80, in _run\n    self._context.run(self._callback, *self._args)\n    │    │            │    │           │    └ <member '_args' of 'Handle' objects>\n    │    │            │    │           └ <Handle Task.task_wakeup(<Future finished result=None>)>\n    │    │            │    └ <member '_callback' of 'Handle' objects>\n    │    │            └ <Handle Task.task_wakeup(<Future finished result=None>)>\n    │    └ <member '_context' of 'Handle' objects>\n    └ <Handle Task.task_wakeup(<Future finished result=None>)>\n\n  File \"C:\\Users\\phili\\PycharmProjects\\GuildsBot\\venv\\lib\\site-packages\\nextcord\\ui\\view.py\", line 390, in _scheduled_task\n    await item.callback(interaction)\n          │    │        └ <nextcord.interactions.Interaction object at 0x000001DFA2AE6400>\n          │    └ functools.partial(<function GuildView.cryo at 0x000001DFA2AEF400>, <GuildView timeout=None children=8>, <Button style=<Button...\n          └ <Button style=<ButtonStyle.primary: 1> url=None disabled=False label='Крио' emoji=None row=None>\n\n  File \"C:\\Users\\phili\\PycharmProjects\\GuildsBot\\slavebot\\views.py\", line 102, in cryo\n    await self.__callback(interaction, button)\n          │               │            └ <Button style=<ButtonStyle.primary: 1> url=None disabled=False label='Крио' emoji=None row=None>\n          │               └ <nextcord.interactions.Interaction object at 0x000001DFA2AE6400>\n          └ <GuildView timeout=None children=8>\n\n> File \"C:\\Users\\phili\\PycharmProjects\\GuildsBot\\slavebot\\views.py\", line 67, in __callback\n    return await self.bad_callback(interaction=inter, message=message)\n                 │    │                        │              └ 'Вы уже начали создавать заявку, если это не так, обратитесь к <@!686207718822117463>.'\n                 │    │                        └ <nextcord.interactions.Interaction object at 0x000001DFA2AE6400>\n                 │    └ <function DataMixin.bad_callback at 0x000001DFA2AEDBD0>\n                 └ <GuildView timeout=None children=8>\n\n  File \"C:\\Users\\phili\\PycharmProjects\\GuildsBot\\slavebot\\utils.py\", line 164, in bad_callback\n    return await interaction.send(\n                 │           └ <function Interaction.send at 0x000001DFA14DB760>\n                 └ <nextcord.interactions.Interaction object at 0x000001DFA2AE6400>\n\n  File \"C:\\Users\\phili\\PycharmProjects\\GuildsBot\\venv\\lib\\site-packages\\nextcord\\interactions.py\", line 523, in send\n    return await self.response.send_message(\n                 │    └ <nextcord.utils.CachedSlotProperty object at 0x000001DFA1419960>\n                 └ <nextcord.interactions.Interaction object at 0x000001DFA2AE6400>\n\n  File \"C:\\Users\\phili\\PycharmProjects\\GuildsBot\\venv\\lib\\site-packages\\nextcord\\interactions.py\", line 852, in send_message\n    await adapter.create_interaction_response(\n          │       └ <function AsyncWebhookAdapter.create_interaction_response at 0x000001DFA14D3D00>\n          └ <nextcord.webhook.async_.AsyncWebhookAdapter object at 0x000001DFA145F9D0>\n\n  File \"C:\\Users\\phili\\PycharmProjects\\GuildsBot\\venv\\lib\\site-packages\\nextcord\\webhook\\async_.py\", line 206, in request\n    raise HTTPException(response, data)\n          │             │         └ {'message': 'Interaction has already been acknowledged.', 'code': 40060}\n          │             └ <ClientResponse(https://discord.com/api/v10/interactions/1003211073459077150/aW50ZXJhY3Rpb246MTAwMzIxMTA3MzQ1OTA3NzE1MDoxM2Rt...\n          └ <class 'nextcord.errors.HTTPException'>\n\nnextcord.errors.HTTPException: 400 Bad Request (error code: 40060): Interaction has already been acknowledged.\n", "record": {"elapsed": {"repr": "0:01:05.812998", "seconds": 65.812998}, "exception": {"type": "HTTPException", "value": "400 Bad Request (error code: 40060): Interaction has already been acknowledged.", "traceback": true}, "extra": {}, "file": {"name": "views.py", "path": "C:\\Users\\phili\\PycharmProjects\\GuildsBot\\slavebot\\views.py"}, "function": "__callback", "level": {"icon": "❌", "name": "ERROR", "no": 40}, "line": 67, "message": "An error has been caught in function '__callback', process 'MainProcess' (16364), thread 'MainThread' (7644):", "module": "views", "name": "slavebot.views", "process": {"id": 16364, "name": "MainProcess"}, "thread": {"id": 7644, "name": "MainThread"}, "time": {"repr": "2022-07-31 11:02:41.055447+03:00", "timestamp": 1659254561.055447}}}
{"text": "2022-07-31T11:21:17.637302+0300 | ERROR      | An error has been caught in function '__callback', process 'MainProcess' (4596), thread 'MainThread' (1576):\nTraceback (most recent call last):\n\n  File \"C:\\Users\\phili\\PycharmProjects\\GuildsBot\\bot.py\", line 105, in <module>\n    run()\n    └ <function run at 0x000001B1645677F0>\n\n  File \"C:\\Users\\phili\\PycharmProjects\\GuildsBot\\bot.py\", line 101, in run\n    bot.run(config.get_token)\n    │   │   │      └ <property object at 0x000001B1642CF150>\n    │   │   └ <_config.Config object at 0x000001B16254D120>\n    │   └ <function Client.run at 0x000001B163011630>\n    └ <nextcord.ext.commands.bot.Bot object at 0x000001B1644EEAD0>\n\n  File \"C:\\Users\\phili\\PycharmProjects\\GuildsBot\\venv\\lib\\site-packages\\nextcord\\client.py\", line 796, in run\n    loop.run_forever()\n    │    └ <function ProactorEventLoop.run_forever at 0x000001B162390DC0>\n    └ <ProactorEventLoop running=True closed=False debug=False>\n\n  File \"C:\\Users\\phili\\AppData\\Local\\Programs\\Python\\Python310\\lib\\asyncio\\windows_events.py\", line 321, in run_forever\n    super().run_forever()\n\n  File \"C:\\Users\\phili\\AppData\\Local\\Programs\\Python\\Python310\\lib\\asyncio\\base_events.py\", line 600, in run_forever\n    self._run_once()\n    │    └ <function BaseEventLoop._run_once at 0x000001B1622E6170>\n    └ <ProactorEventLoop running=True closed=False debug=False>\n\n  File \"C:\\Users\\phili\\AppData\\Local\\Programs\\Python\\Python310\\lib\\asyncio\\base_events.py\", line 1896, in _run_once\n    handle._run()\n    │      └ <function Handle._run at 0x000001B162281990>\n    └ <Handle Task.task_wakeup(<Future finished result=None>)>\n\n  File \"C:\\Users\\phili\\AppData\\Local\\Programs\\Python\\Python310\\lib\\asyncio\\events.py\", line 80, in _run\n    self._context.run(self._callback, *self._args)\n    │    │            │    │           │    └ <member '_args' of 'Handle' objects>\n    │    │            │    │           └ <Handle Task.task_wakeup(<Future finished result=None>)>\n    │    │            │    └ <member '_callback' of 'Handle' objects>\n    │    │            └ <Handle Task.task_wakeup(<Future finished result=None>)>\n    │    └ <member '_context' of 'Handle' objects>\n    └ <Handle Task.task_wakeup(<Future finished result=None>)>\n\n  File \"C:\\Users\\phili\\PycharmProjects\\GuildsBot\\venv\\lib\\site-packages\\nextcord\\ui\\view.py\", line 390, in _scheduled_task\n    await item.callback(interaction)\n          │    │        └ <nextcord.interactions.Interaction object at 0x000001B164E50520>\n          │    └ functools.partial(<function GuildView.cryo at 0x000001B16454B760>, <GuildView timeout=None children=8>, <Button style=<Button...\n          └ <Button style=<ButtonStyle.primary: 1> url=None disabled=False label='Крио' emoji=None row=None>\n\n  File \"C:\\Users\\phili\\PycharmProjects\\GuildsBot\\slavebot\\views.py\", line 102, in cryo\n    await self.__callback(interaction, button)\n          │               │            └ <Button style=<ButtonStyle.primary: 1> url=None disabled=False label='Крио' emoji=None row=None>\n          │               └ <nextcord.interactions.Interaction object at 0x000001B164E50520>\n          └ <GuildView timeout=None children=8>\n\n> File \"C:\\Users\\phili\\PycharmProjects\\GuildsBot\\slavebot\\views.py\", line 67, in __callback\n    return await self.bad_callback(interaction=inter, message=message)\n                 │    │                        │              └ 'Вы уже начали создавать заявку, если это не так, обратитесь к <@!686207718822117463>.'\n                 │    │                        └ <nextcord.interactions.Interaction object at 0x000001B164E50520>\n                 │    └ <function DataMixin.bad_callback at 0x000001B164549B40>\n                 └ <GuildView timeout=None children=8>\n\n  File \"C:\\Users\\phili\\PycharmProjects\\GuildsBot\\slavebot\\utils.py\", line 164, in bad_callback\n    return await interaction.send(\n                 │           └ <function Interaction.send at 0x000001B162F2B760>\n                 └ <nextcord.interactions.Interaction object at 0x000001B164E50520>\n\n  File \"C:\\Users\\phili\\PycharmProjects\\GuildsBot\\venv\\lib\\site-packages\\nextcord\\interactions.py\", line 523, in send\n    return await self.response.send_message(\n                 │    └ <nextcord.utils.CachedSlotProperty object at 0x000001B162E6DC60>\n                 └ <nextcord.interactions.Interaction object at 0x000001B164E50520>\n\n  File \"C:\\Users\\phili\\PycharmProjects\\GuildsBot\\venv\\lib\\site-packages\\nextcord\\interactions.py\", line 852, in send_message\n    await adapter.create_interaction_response(\n          │       └ <function AsyncWebhookAdapter.create_interaction_response at 0x000001B162F23D00>\n          └ <nextcord.webhook.async_.AsyncWebhookAdapter object at 0x000001B162EABCD0>\n\n  File \"C:\\Users\\phili\\PycharmProjects\\GuildsBot\\venv\\lib\\site-packages\\nextcord\\webhook\\async_.py\", line 206, in request\n    raise HTTPException(response, data)\n          │             │         └ {'message': 'Interaction has already been acknowledged.', 'code': 40060}\n          │             └ <ClientResponse(https://discord.com/api/v10/interactions/1003215756328194048/aW50ZXJhY3Rpb246MTAwMzIxNTc1NjMyODE5NDA0ODplZkhS...\n          └ <class 'nextcord.errors.HTTPException'>\n\nnextcord.errors.HTTPException: 400 Bad Request (error code: 40060): Interaction has already been acknowledged.\n", "record": {"elapsed": {"repr": "0:07:03.441622", "seconds": 423.441622}, "exception": {"type": "HTTPException", "value": "400 Bad Request (error code: 40060): Interaction has already been acknowledged.", "traceback": true}, "extra": {}, "file": {"name": "views.py", "path": "C:\\Users\\phili\\PycharmProjects\\GuildsBot\\slavebot\\views.py"}, "function": "__callback", "level": {"icon": "❌", "name": "ERROR", "no": 40}, "line": 67, "message": "An error has been caught in function '__callback', process 'MainProcess' (4596), thread 'MainThread' (1576):", "module": "views", "name": "slavebot.views", "process": {"id": 4596, "name": "MainProcess"}, "thread": {"id": 1576, "name": "MainThread"}, "time": {"repr": "2022-07-31 11:21:17.637302+03:00", "timestamp": 1659255677.637302}}}
{"text": "2022-07-31T11:31:42.324134+0300 | ERROR      | An error has been caught in function '__callback', process 'MainProcess' (10572), thread 'MainThread' (12604):\nTraceback (most recent call last):\n\n  File \"C:\\Users\\phili\\PycharmProjects\\GuildsBot\\bot.py\", line 105, in <module>\n    run()\n    └ <function run at 0x000001A14B3137F0>\n\n  File \"C:\\Users\\phili\\PycharmProjects\\GuildsBot\\bot.py\", line 101, in run\n    bot.run(config.get_token)\n    │   │   │      └ <property object at 0x000001A14B07F150>\n    │   │   └ <_config.Config object at 0x000001A1496CD120>\n    │   └ <function Client.run at 0x000001A149DC1630>\n    └ <nextcord.ext.commands.bot.Bot object at 0x000001A14B319D80>\n\n  File \"C:\\Users\\phili\\PycharmProjects\\GuildsBot\\venv\\lib\\site-packages\\nextcord\\client.py\", line 796, in run\n    loop.run_forever()\n    │    └ <function ProactorEventLoop.run_forever at 0x000001A1490F0DC0>\n    └ <ProactorEventLoop running=True closed=False debug=False>\n\n  File \"C:\\Users\\phili\\AppData\\Local\\Programs\\Python\\Python310\\lib\\asyncio\\windows_events.py\", line 321, in run_forever\n    super().run_forever()\n\n  File \"C:\\Users\\phili\\AppData\\Local\\Programs\\Python\\Python310\\lib\\asyncio\\base_events.py\", line 600, in run_forever\n    self._run_once()\n    │    └ <function BaseEventLoop._run_once at 0x000001A149046170>\n    └ <ProactorEventLoop running=True closed=False debug=False>\n\n  File \"C:\\Users\\phili\\AppData\\Local\\Programs\\Python\\Python310\\lib\\asyncio\\base_events.py\", line 1896, in _run_once\n    handle._run()\n    │      └ <function Handle._run at 0x000001A148FE1990>\n    └ <Handle Task.task_wakeup(<Future finished result=None>)>\n\n  File \"C:\\Users\\phili\\AppData\\Local\\Programs\\Python\\Python310\\lib\\asyncio\\events.py\", line 80, in _run\n    self._context.run(self._callback, *self._args)\n    │    │            │    │           │    └ <member '_args' of 'Handle' objects>\n    │    │            │    │           └ <Handle Task.task_wakeup(<Future finished result=None>)>\n    │    │            │    └ <member '_callback' of 'Handle' objects>\n    │    │            └ <Handle Task.task_wakeup(<Future finished result=None>)>\n    │    └ <member '_context' of 'Handle' objects>\n    └ <Handle Task.task_wakeup(<Future finished result=None>)>\n\n  File \"C:\\Users\\phili\\PycharmProjects\\GuildsBot\\venv\\lib\\site-packages\\nextcord\\ui\\view.py\", line 390, in _scheduled_task\n    await item.callback(interaction)\n          │    │        └ <nextcord.interactions.Interaction object at 0x000001A14B2E25A0>\n          │    └ functools.partial(<function GuildView.pyro at 0x000001A14B2EF640>, <GuildView timeout=None children=8>, <Button style=<Button...\n          └ <Button style=<ButtonStyle.primary: 1> url=None disabled=False label='Пиро' emoji=None row=None>\n\n  File \"C:\\Users\\phili\\PycharmProjects\\GuildsBot\\slavebot\\views.py\", line 98, in pyro\n    await self.__callback(interaction, button)\n          │               │            └ <Button style=<ButtonStyle.primary: 1> url=None disabled=False label='Пиро' emoji=None row=None>\n          │               └ <nextcord.interactions.Interaction object at 0x000001A14B2E25A0>\n          └ <GuildView timeout=None children=8>\n\n> File \"C:\\Users\\phili\\PycharmProjects\\GuildsBot\\slavebot\\views.py\", line 67, in __callback\n    return await self.bad_callback(interaction=inter, message=message)\n                 │    │                        │              └ 'Вы уже находитесь в гильдии, попросите вашего мастера изнать вас. \\n\\n Также вы можете написать /leave или +лив'\n                 │    │                        └ <nextcord.interactions.Interaction object at 0x000001A14B2E25A0>\n                 │    └ <function DataMixin.bad_callback at 0x000001A14B2EDBD0>\n                 └ <GuildView timeout=None children=8>\n\n  File \"C:\\Users\\phili\\PycharmProjects\\GuildsBot\\slavebot\\utils.py\", line 164, in bad_callback\n    return await interaction.send(\n                 │           └ <function Interaction.send at 0x000001A149CDB760>\n                 └ <nextcord.interactions.Interaction object at 0x000001A14B2E25A0>\n\n  File \"C:\\Users\\phili\\PycharmProjects\\GuildsBot\\venv\\lib\\site-packages\\nextcord\\interactions.py\", line 523, in send\n    return await self.response.send_message(\n                 │    └ <nextcord.utils.CachedSlotProperty object at 0x000001A149C1DC30>\n                 └ <nextcord.interactions.Interaction object at 0x000001A14B2E25A0>\n\n  File \"C:\\Users\\phili\\PycharmProjects\\GuildsBot\\venv\\lib\\site-packages\\nextcord\\interactions.py\", line 852, in send_message\n    await adapter.create_interaction_response(\n          │       └ <function AsyncWebhookAdapter.create_interaction_response at 0x000001A149CD3D00>\n          └ <nextcord.webhook.async_.AsyncWebhookAdapter object at 0x000001A149C5BCA0>\n\n  File \"C:\\Users\\phili\\PycharmProjects\\GuildsBot\\venv\\lib\\site-packages\\nextcord\\webhook\\async_.py\", line 206, in request\n    raise HTTPException(response, data)\n          │             │         └ {'message': 'Interaction has already been acknowledged.', 'code': 40060}\n          │             └ <ClientResponse(https://discord.com/api/v10/interactions/1003218377063542844/aW50ZXJhY3Rpb246MTAwMzIxODM3NzA2MzU0Mjg0NDp6djZj...\n          └ <class 'nextcord.errors.HTTPException'>\n\nnextcord.errors.HTTPException: 400 Bad Request (error code: 40060): Interaction has already been acknowledged.\n", "record": {"elapsed": {"repr": "0:06:24.772532", "seconds": 384.772532}, "exception": {"type": "HTTPException", "value": "400 Bad Request (error code: 40060): Interaction has already been acknowledged.", "traceback": true}, "extra": {}, "file": {"name": "views.py", "path": "C:\\Users\\phili\\PycharmProjects\\GuildsBot\\slavebot\\views.py"}, "function": "__callback", "level": {"icon": "❌", "name": "ERROR", "no": 40}, "line": 67, "message": "An error has been caught in function '__callback', process 'MainProcess' (10572), thread 'MainThread' (12604):", "module": "views", "name": "slavebot.views", "process": {"id": 10572, "name": "MainProcess"}, "thread": {"id": 12604, "name": "MainThread"}, "time": {"repr": "2022-07-31 11:31:42.324134+03:00", "timestamp": 1659256302.324134}}}
{"text": "2022-07-31T11:31:54.059133+0300 | ERROR      | An error has been caught in function '__callback', process 'MainProcess' (10572), thread 'MainThread' (12604):\nTraceback (most recent call last):\n\n  File \"C:\\Users\\phili\\PycharmProjects\\GuildsBot\\bot.py\", line 105, in <module>\n    run()\n    └ <function run at 0x000001A14B3137F0>\n\n  File \"C:\\Users\\phili\\PycharmProjects\\GuildsBot\\bot.py\", line 101, in run\n    bot.run(config.get_token)\n    │   │   │      └ <property object at 0x000001A14B07F150>\n    │   │   └ <_config.Config object at 0x000001A1496CD120>\n    │   └ <function Client.run at 0x000001A149DC1630>\n    └ <nextcord.ext.commands.bot.Bot object at 0x000001A14B319D80>\n\n  File \"C:\\Users\\phili\\PycharmProjects\\GuildsBot\\venv\\lib\\site-packages\\nextcord\\client.py\", line 796, in run\n    loop.run_forever()\n    │    └ <function ProactorEventLoop.run_forever at 0x000001A1490F0DC0>\n    └ <ProactorEventLoop running=True closed=False debug=False>\n\n  File \"C:\\Users\\phili\\AppData\\Local\\Programs\\Python\\Python310\\lib\\asyncio\\windows_events.py\", line 321, in run_forever\n    super().run_forever()\n\n  File \"C:\\Users\\phili\\AppData\\Local\\Programs\\Python\\Python310\\lib\\asyncio\\base_events.py\", line 600, in run_forever\n    self._run_once()\n    │    └ <function BaseEventLoop._run_once at 0x000001A149046170>\n    └ <ProactorEventLoop running=True closed=False debug=False>\n\n  File \"C:\\Users\\phili\\AppData\\Local\\Programs\\Python\\Python310\\lib\\asyncio\\base_events.py\", line 1896, in _run_once\n    handle._run()\n    │      └ <function Handle._run at 0x000001A148FE1990>\n    └ <Handle Task.task_wakeup(<Future finished result=None>)>\n\n  File \"C:\\Users\\phili\\AppData\\Local\\Programs\\Python\\Python310\\lib\\asyncio\\events.py\", line 80, in _run\n    self._context.run(self._callback, *self._args)\n    │    │            │    │           │    └ <member '_args' of 'Handle' objects>\n    │    │            │    │           └ <Handle Task.task_wakeup(<Future finished result=None>)>\n    │    │            │    └ <member '_callback' of 'Handle' objects>\n    │    │            └ <Handle Task.task_wakeup(<Future finished result=None>)>\n    │    └ <member '_context' of 'Handle' objects>\n    └ <Handle Task.task_wakeup(<Future finished result=None>)>\n\n  File \"C:\\Users\\phili\\PycharmProjects\\GuildsBot\\venv\\lib\\site-packages\\nextcord\\ui\\view.py\", line 390, in _scheduled_task\n    await item.callback(interaction)\n          │    │        └ <nextcord.interactions.Interaction object at 0x000001A14B2E3D30>\n          │    └ functools.partial(<function GuildView.pyro at 0x000001A14B2EF640>, <GuildView timeout=None children=8>, <Button style=<Button...\n          └ <Button style=<ButtonStyle.primary: 1> url=None disabled=False label='Пиро' emoji=None row=None>\n\n  File \"C:\\Users\\phili\\PycharmProjects\\GuildsBot\\slavebot\\views.py\", line 98, in pyro\n    await self.__callback(interaction, button)\n          │               │            └ <Button style=<ButtonStyle.primary: 1> url=None disabled=False label='Пиро' emoji=None row=None>\n          │               └ <nextcord.interactions.Interaction object at 0x000001A14B2E3D30>\n          └ <GuildView timeout=None children=8>\n\n> File \"C:\\Users\\phili\\PycharmProjects\\GuildsBot\\slavebot\\views.py\", line 67, in __callback\n    return await self.bad_callback(interaction=inter, message=message)\n                 │    │                        │              └ 'Вы уже находитесь в гильдии, попросите вашего мастера изнать вас. \\n\\n Также вы можете написать /leave или +лив'\n                 │    │                        └ <nextcord.interactions.Interaction object at 0x000001A14B2E3D30>\n                 │    └ <function DataMixin.bad_callback at 0x000001A14B2EDBD0>\n                 └ <GuildView timeout=None children=8>\n\n  File \"C:\\Users\\phili\\PycharmProjects\\GuildsBot\\slavebot\\utils.py\", line 164, in bad_callback\n    return await interaction.send(\n                 │           └ <function Interaction.send at 0x000001A149CDB760>\n                 └ <nextcord.interactions.Interaction object at 0x000001A14B2E3D30>\n\n  File \"C:\\Users\\phili\\PycharmProjects\\GuildsBot\\venv\\lib\\site-packages\\nextcord\\interactions.py\", line 523, in send\n    return await self.response.send_message(\n                 │    └ <nextcord.utils.CachedSlotProperty object at 0x000001A149C1DC30>\n                 └ <nextcord.interactions.Interaction object at 0x000001A14B2E3D30>\n\n  File \"C:\\Users\\phili\\PycharmProjects\\GuildsBot\\venv\\lib\\site-packages\\nextcord\\interactions.py\", line 852, in send_message\n    await adapter.create_interaction_response(\n          │       └ <function AsyncWebhookAdapter.create_interaction_response at 0x000001A149CD3D00>\n          └ <nextcord.webhook.async_.AsyncWebhookAdapter object at 0x000001A149C5BCA0>\n\n  File \"C:\\Users\\phili\\PycharmProjects\\GuildsBot\\venv\\lib\\site-packages\\nextcord\\webhook\\async_.py\", line 206, in request\n    raise HTTPException(response, data)\n          │             │         └ {'message': 'Interaction has already been acknowledged.', 'code': 40060}\n          │             └ <ClientResponse(https://discord.com/api/v10/interactions/1003218427969798174/aW50ZXJhY3Rpb246MTAwMzIxODQyNzk2OTc5ODE3NDpBeXBI...\n          └ <class 'nextcord.errors.HTTPException'>\n\nnextcord.errors.HTTPException: 400 Bad Request (error code: 40060): Interaction has already been acknowledged.\n", "record": {"elapsed": {"repr": "0:06:36.507531", "seconds": 396.507531}, "exception": {"type": "HTTPException", "value": "400 Bad Request (error code: 40060): Interaction has already been acknowledged.", "traceback": true}, "extra": {}, "file": {"name": "views.py", "path": "C:\\Users\\phili\\PycharmProjects\\GuildsBot\\slavebot\\views.py"}, "function": "__callback", "level": {"icon": "❌", "name": "ERROR", "no": 40}, "line": 67, "message": "An error has been caught in function '__callback', process 'MainProcess' (10572), thread 'MainThread' (12604):", "module": "views", "name": "slavebot.views", "process": {"id": 10572, "name": "MainProcess"}, "thread": {"id": 12604, "name": "MainThread"}, "time": {"repr": "2022-07-31 11:31:54.059133+03:00", "timestamp": 1659256314.059133}}}
{"text": "2022-07-31T21:19:20.066703+0300 | ERROR      | Ошибка при получении инвайта для гильдии Test server \"Mizu\"\n\n403 Forbidden (error code: 50013): Missing Permissions\n", "record": {"elapsed": {"repr": "0:00:23.244000", "seconds": 23.244}, "exception": null, "extra": {}, "file": {"name": "utils.py", "path": "C:\\Users\\phili\\PycharmProjects\\GuildsBot\\slavebot\\utils.py"}, "function": "get_guild_invite", "level": {"icon": "❌", "name": "ERROR", "no": 40}, "line": 199, "message": "Ошибка при получении инвайта для гильдии Test server \"Mizu\"\n\n403 Forbidden (error code: 50013): Missing Permissions", "module": "utils", "name": "slavebot.utils", "process": {"id": 17852, "name": "MainProcess"}, "thread": {"id": 11580, "name": "MainThread"}, "time": {"repr": "2022-07-31 21:19:20.066703+03:00", "timestamp": 1659291560.066703}}}
{"text": "2022-07-31T21:20:23.859765+0300 | ERROR      | Ошибка при получении инвайта для гильдии Test server \"Mizu\"\n\n403 Forbidden (error code: 50013): Missing Permissions\n", "record": {"elapsed": {"repr": "0:00:08.718000", "seconds": 8.718}, "exception": null, "extra": {}, "file": {"name": "utils.py", "path": "C:\\Users\\phili\\PycharmProjects\\GuildsBot\\slavebot\\utils.py"}, "function": "get_guild_invite", "level": {"icon": "❌", "name": "ERROR", "no": 40}, "line": 199, "message": "Ошибка при получении инвайта для гильдии Test server \"Mizu\"\n\n403 Forbidden (error code: 50013): Missing Permissions", "module": "utils", "name": "slavebot.utils", "process": {"id": 19000, "name": "MainProcess"}, "thread": {"id": 12876, "name": "MainThread"}, "time": {"repr": "2022-07-31 21:20:23.859765+03:00", "timestamp": 1659291623.859765}}}
{"text": "2022-07-31T21:24:21.370509+0300 | ERROR      | Ошибка при получении инвайта для гильдии Test server \"Mizu\"\n\n403 Forbidden (error code: 50013): Missing Permissions\n", "record": {"elapsed": {"repr": "0:04:06.228744", "seconds": 246.228744}, "exception": null, "extra": {}, "file": {"name": "utils.py", "path": "C:\\Users\\phili\\PycharmProjects\\GuildsBot\\slavebot\\utils.py"}, "function": "get_guild_invite", "level": {"icon": "❌", "name": "ERROR", "no": 40}, "line": 199, "message": "Ошибка при получении инвайта для гильдии Test server \"Mizu\"\n\n403 Forbidden (error code: 50013): Missing Permissions", "module": "utils", "name": "slavebot.utils", "process": {"id": 19000, "name": "MainProcess"}, "thread": {"id": 12876, "name": "MainThread"}, "time": {"repr": "2022-07-31 21:24:21.370509+03:00", "timestamp": 1659291861.370509}}}
{"text": "2022-07-31T21:26:00.536514+0300 | ERROR      | Ошибка при получении инвайта для гильдии Test server \"Mizu\"\n\n403 Forbidden (error code: 50013): Missing Permissions\n", "record": {"elapsed": {"repr": "0:05:45.394749", "seconds": 345.394749}, "exception": null, "extra": {}, "file": {"name": "utils.py", "path": "C:\\Users\\phili\\PycharmProjects\\GuildsBot\\slavebot\\utils.py"}, "function": "get_guild_invite", "level": {"icon": "❌", "name": "ERROR", "no": 40}, "line": 199, "message": "Ошибка при получении инвайта для гильдии Test server \"Mizu\"\n\n403 Forbidden (error code: 50013): Missing Permissions", "module": "utils", "name": "slavebot.utils", "process": {"id": 19000, "name": "MainProcess"}, "thread": {"id": 12876, "name": "MainThread"}, "time": {"repr": "2022-07-31 21:26:00.536514+03:00", "timestamp": 1659291960.536514}}}
{"text": "2022-07-31T21:27:15.103514+0300 | ERROR      | Ошибка при получении инвайта для гильдии Test server \"Mizu\"\n\n403 Forbidden (error code: 50013): Missing Permissions\n", "record": {"elapsed": {"repr": "0:06:59.961749", "seconds": 419.961749}, "exception": null, "extra": {}, "file": {"name": "utils.py", "path": "C:\\Users\\phili\\PycharmProjects\\GuildsBot\\slavebot\\utils.py"}, "function": "get_guild_invite", "level": {"icon": "❌", "name": "ERROR", "no": 40}, "line": 199, "message": "Ошибка при получении инвайта для гильдии Test server \"Mizu\"\n\n403 Forbidden (error code: 50013): Missing Permissions", "module": "utils", "name": "slavebot.utils", "process": {"id": 19000, "name": "MainProcess"}, "thread": {"id": 12876, "name": "MainThread"}, "time": {"repr": "2022-07-31 21:27:15.103514+03:00", "timestamp": 1659292035.103514}}}
{"text": "2022-07-31T21:30:50.322026+0300 | ERROR      | Ошибка при получении инвайта для гильдии Test server \"Mizu\"\n\n403 Forbidden (error code: 50013): Missing Permissions\n", "record": {"elapsed": {"repr": "0:00:59.559996", "seconds": 59.559996}, "exception": null, "extra": {}, "file": {"name": "utils.py", "path": "C:\\Users\\phili\\PycharmProjects\\GuildsBot\\slavebot\\utils.py"}, "function": "get_guild_invite", "level": {"icon": "❌", "name": "ERROR", "no": 40}, "line": 199, "message": "Ошибка при получении инвайта для гильдии Test server \"Mizu\"\n\n403 Forbidden (error code: 50013): Missing Permissions", "module": "utils", "name": "slavebot.utils", "process": {"id": 3444, "name": "MainProcess"}, "thread": {"id": 6096, "name": "MainThread"}, "time": {"repr": "2022-07-31 21:30:50.322026+03:00", "timestamp": 1659292250.322026}}}
{"text": "2022-07-31T21:33:35.096540+0300 | ERROR      | Ошибка при получении инвайта для гильдии Test server \"Mizu\"\n\n403 Forbidden (error code: 50013): Missing Permissions\n", "record": {"elapsed": {"repr": "0:00:24.809989", "seconds": 24.809989}, "exception": null, "extra": {}, "file": {"name": "utils.py", "path": "C:\\Users\\phili\\PycharmProjects\\GuildsBot\\slavebot\\utils.py"}, "function": "get_guild_invite", "level": {"icon": "❌", "name": "ERROR", "no": 40}, "line": 199, "message": "Ошибка при получении инвайта для гильдии Test server \"Mizu\"\n\n403 Forbidden (error code: 50013): Missing Permissions", "module": "utils", "name": "slavebot.utils", "process": {"id": 16328, "name": "MainProcess"}, "thread": {"id": 14612, "name": "MainThread"}, "time": {"repr": "2022-07-31 21:33:35.096540+03:00", "timestamp": 1659292415.09654}}}
{"text": "2022-07-31T21:40:36.628539+0300 | ERROR      | Ошибка при получении инвайта для гильдии Test server \"Mizu\"\n\n403 Forbidden (error code: 50013): Missing Permissions\n", "record": {"elapsed": {"repr": "0:07:26.341988", "seconds": 446.341988}, "exception": null, "extra": {}, "file": {"name": "utils.py", "path": "C:\\Users\\phili\\PycharmProjects\\GuildsBot\\slavebot\\utils.py"}, "function": "get_guild_invite", "level": {"icon": "❌", "name": "ERROR", "no": 40}, "line": 199, "message": "Ошибка при получении инвайта для гильдии Test server \"Mizu\"\n\n403 Forbidden (error code: 50013): Missing Permissions", "module": "utils", "name": "slavebot.utils", "process": {"id": 16328, "name": "MainProcess"}, "thread": {"id": 14612, "name": "MainThread"}, "time": {"repr": "2022-07-31 21:40:36.628539+03:00", "timestamp": 1659292836.628539}}}
{"text": "2022-07-31T21:42:37.796541+0300 | ERROR      | Ошибка при получении инвайта для гильдии Test server \"Mizu\"\n\n403 Forbidden (error code: 50013): Missing Permissions\n", "record": {"elapsed": {"repr": "0:00:37.918001", "seconds": 37.918001}, "exception": null, "extra": {}, "file": {"name": "utils.py", "path": "C:\\Users\\phili\\PycharmProjects\\GuildsBot\\slavebot\\utils.py"}, "function": "get_guild_invite", "level": {"icon": "❌", "name": "ERROR", "no": 40}, "line": 199, "message": "Ошибка при получении инвайта для гильдии Test server \"Mizu\"\n\n403 Forbidden (error code: 50013): Missing Permissions", "module": "utils", "name": "slavebot.utils", "process": {"id": 5640, "name": "MainProcess"}, "thread": {"id": 15928, "name": "MainThread"}, "time": {"repr": "2022-07-31 21:42:37.796541+03:00", "timestamp": 1659292957.796541}}}
{"text": "2022-07-31T21:46:25.828102+0300 | ERROR      | Ошибка при получении инвайта для гильдии Test server \"Mizu\"\n\n403 Forbidden (error code: 50013): Missing Permissions\n", "record": {"elapsed": {"repr": "0:02:36.379561", "seconds": 156.379561}, "exception": null, "extra": {}, "file": {"name": "utils.py", "path": "C:\\Users\\phili\\PycharmProjects\\GuildsBot\\slavebot\\utils.py"}, "function": "get_guild_invite", "level": {"icon": "❌", "name": "ERROR", "no": 40}, "line": 199, "message": "Ошибка при получении инвайта для гильдии Test server \"Mizu\"\n\n403 Forbidden (error code: 50013): Missing Permissions", "module": "utils", "name": "slavebot.utils", "process": {"id": 8116, "name": "MainProcess"}, "thread": {"id": 4136, "name": "MainThread"}, "time": {"repr": "2022-07-31 21:46:25.828102+03:00", "timestamp": 1659293185.828102}}}
{"text": "2022-07-31T21:52:46.326624+0300 | ERROR      | Ошибка при получении инвайта для гильдии Test server \"Mizu\"\n\n403 Forbidden (error code: 50013): Missing Permissions\n", "record": {"elapsed": {"repr": "0:08:56.878083", "seconds": 536.878083}, "exception": null, "extra": {}, "file": {"name": "utils.py", "path": "C:\\Users\\phili\\PycharmProjects\\GuildsBot\\slavebot\\utils.py"}, "function": "get_guild_invite", "level": {"icon": "❌", "name": "ERROR", "no": 40}, "line": 199, "message": "Ошибка при получении инвайта для гильдии Test server \"Mizu\"\n\n403 Forbidden (error code: 50013): Missing Permissions", "module": "utils", "name": "slavebot.utils", "process": {"id": 8116, "name": "MainProcess"}, "thread": {"id": 4136, "name": "MainThread"}, "time": {"repr": "2022-07-31 21:52:46.326624+03:00", "timestamp": 1659293566.326624}}}
